<?xml version="1.0" encoding="utf-8"?>
<!-- This URDF was automatically created by SolidWorks to URDF Exporter! Originally created by Stephen Brawner (brawner@gmail.com) 
     Commit Version: 1.5.1-0-g916b5db  Build Version: 1.5.7152.31018
     For more information, please see http://wiki.ros.org/sw_urdf_exporter -->
<robot
  name="kuka_urdf">
  <link
    name="base_link">
    <inertial>
      <origin
        xyz="0.594999503266221 -0.4282710940644 1.10982737374864"
        rpy="0 0 0" />
      <mass
        value="170.0096095409" />
      <inertia
        ixx="15.423191189605"
        ixy="-0.769988015650329"
        ixz="-0.334753403251733"
        iyy="21.0934964927136"
        iyz="-0.217841140427876"
        izz="14.6780515524527" />
    </inertial>
    <visual>
      <origin
        xyz="0 0 0"
        rpy="0 0 0" />
      <geometry>
        <mesh
          filename="package://kuka_urdf/meshes/base_link.STL" />
      </geometry>
      <material
        name="">
        <color
          rgba="0.752941176470588 0.752941176470588 0.752941176470588 1" />
      </material>
    </visual>
    <collision>
      <origin
        xyz="0 0 0"
        rpy="0 0 0" />
      <geometry>
        <mesh
          filename="package://kuka_urdf/meshes/base_link.STL" />
      </geometry>
    </collision>
  </link>
  <link
    name="link1">
    <inertial>
      <origin
        xyz="0.00796741917398325 0.00201869055885101 0.115718073498994"
        rpy="0 0 0" />
      <mass
        value="6.27526433045052" />
      <inertia
        ixx="0.0762054973038654"
        ixy="9.82188144569856E-06"
        ixz="-0.00530053527199466"
        iyy="0.0500772495062891"
        iyz="-0.000515039637430019"
        izz="0.0562692167501734" />
    </inertial>
    <visual>
      <origin
        xyz="0 0 0"
        rpy="0 0 0" />
      <geometry>
        <mesh
          filename="package://kuka_urdf/meshes/link1.STL" />
      </geometry>
      <material
        name="">
        <color
          rgba="0.792156862745098 0.819607843137255 0.933333333333333 1" />
      </material>
    </visual>
    <collision>
      <origin
        xyz="0 0 0"
        rpy="0 0 0" />
      <geometry>
        <mesh
          filename="package://kuka_urdf/meshes/link1.STL" />
      </geometry>
    </collision>
  </link>
  <joint
    name="joint1"
    type="revolute">
    <origin
      xyz="0.8275 -0.43219 1.3595"
      rpy="0 0 0" />
    <parent
      link="base_link" />
    <child
      link="link1" />
    <axis
      xyz="0 0 1" />
    <limit
      lower="-6.28"
      upper="6.28"
      effort="500"
      velocity="2" />
  </joint>
  <link
    name="link2">
    <inertial>
      <origin
        xyz="-0.00525474427373662 -0.00581945166654141 0.131443823398878"
        rpy="0 0 0" />
      <mass
        value="7.36258419830385" />
      <inertia
        ixx="0.151415780044457"
        ixy="-1.49717820004814E-05"
        ixz="0.000868975891906836"
        iyy="0.135639503717904"
        iyz="0.00168356968157077"
        izz="0.0384883579896224" />
    </inertial>
    <visual>
      <origin
        xyz="0 0 0"
        rpy="0 0 0" />
      <geometry>
        <mesh
          filename="package://kuka_urdf/meshes/link2.STL" />
      </geometry>
      <material
        name="">
        <color
          rgba="0.792156862745098 0.819607843137255 0.933333333333333 1" />
      </material>
    </visual>
    <collision>
      <origin
        xyz="0 0 0"
        rpy="0 0 0" />
      <geometry>
        <mesh
          filename="package://kuka_urdf/meshes/link2.STL" />
      </geometry>
    </collision>
  </link>
  <joint
    name="joint2"
    type="revolute">
    <origin
      xyz="0.025 0 0.183"
      rpy="0 0 0" />
    <parent
      link="link1" />
    <child
      link="link2" />
    <axis
      xyz="0 -1 0" />
    <limit
      lower="-6.28"
      upper="6.28"
      effort="500"
      velocity="2" />
  </joint>
  <link
    name="link3">
    <inertial>
      <origin
        xyz="0.0158897369187757 0.00377551618976696 0.0103622040607538"
        rpy="0 0 0" />
      <mass
        value="2.90698496734874" />
      <inertia
        ixx="0.00835937630352445"
        ixy="3.52504576818559E-05"
        ixz="-0.00140858847686176"
        iyy="0.0112132449448129"
        iyz="1.88954255172529E-05"
        izz="0.0100277382418828" />
    </inertial>
    <visual>
      <origin
        xyz="0 0 0"
        rpy="0 0 0" />
      <geometry>
        <mesh
          filename="package://kuka_urdf/meshes/link3.STL" />
      </geometry>
      <material
        name="">
        <color
          rgba="0.8 1 0.2 1" />
      </material>
    </visual>
    <collision>
      <origin
        xyz="0 0 0"
        rpy="0 0 0" />
      <geometry>
        <mesh
          filename="package://kuka_urdf/meshes/link3.STL" />
      </geometry>
    </collision>
  </link>
  <joint
    name="joint3"
    type="revolute">
    <origin
      xyz="0 0 0.315"
      rpy="0 0 0" />
    <parent
      link="link2" />
    <child
      link="link3" />
    <axis
      xyz="0 -1 0" />
    <limit
      lower="-6.28"
      upper="6.28"
      effort="500"
      velocity="2" />
  </joint>
  <link
    name="link4">
    <inertial>
      <origin
        xyz="0.123981724214701 0.0034688211324434 0.000289159358459745"
        rpy="0 0 0" />
      <mass
        value="2.75654210425904" />
      <inertia
        ixx="0.00584711964625554"
        ixy="-0.000156323136874248"
        ixz="5.19522467907712E-06"
        iyy="0.0156113113263976"
        iyz="1.44373593566699E-05"
        izz="0.0172713088405886" />
    </inertial>
    <visual>
      <origin
        xyz="0 0 0"
        rpy="0 0 0" />
      <geometry>
        <mesh
          filename="package://kuka_urdf/meshes/link4.STL" />
      </geometry>
      <material
        name="">
        <color
          rgba="0.792156862745098 0.819607843137255 0.933333333333333 1" />
      </material>
    </visual>
    <collision>
      <origin
        xyz="0 0 0"
        rpy="0 0 0" />
      <geometry>
        <mesh
          filename="package://kuka_urdf/meshes/link4.STL" />
      </geometry>
    </collision>
  </link>
  <joint
    name="joint4"
    type="revolute">
    <origin
      xyz="0.10695 0.003 0.035"
      rpy="0 0 0" />
    <parent
      link="link3" />
    <child
      link="link4" />
    <axis
      xyz="-1 0 0" />
    <limit
      lower="-6.28"
      upper="6.28"
      effort="500"
      velocity="2" />
  </joint>
  <link
    name="link5">
    <inertial>
      <origin
        xyz="0.0157891702201667 0.00191367544264814 -3.03958143459404E-05"
        rpy="0 0 0" />
      <mass
        value="0.442067197041372" />
      <inertia
        ixx="0.000318420757784039"
        ixy="1.663144203727E-05"
        ixz="3.2063967174793E-07"
        iyy="0.000528480030475778"
        iyz="3.23079721639523E-07"
        izz="0.000562282896446415" />
    </inertial>
    <visual>
      <origin
        xyz="0 0 0"
        rpy="0 0 0" />
      <geometry>
        <mesh
          filename="package://kuka_urdf/meshes/link5.STL" />
      </geometry>
      <material
        name="">
        <color
          rgba="0.792156862745098 0.819607843137255 0.933333333333333 1" />
      </material>
    </visual>
    <collision>
      <origin
        xyz="0 0 0"
        rpy="0 0 0" />
      <geometry>
        <mesh
          filename="package://kuka_urdf/meshes/link5.STL" />
      </geometry>
    </collision>
  </link>
  <joint
    name="joint5"
    type="revolute">
    <origin
      xyz="0.25805 0 0"
      rpy="0 0 0" />
    <parent
      link="link4" />
    <child
      link="link5" />
    <axis
      xyz="0 1 0" />
    <limit
      lower="-6.28"
      upper="6.28"
      effort="500"
      velocity="2" />
  </joint>
  <link
    name="link6">
    <inertial>
      <origin
        xyz="0.005980331956146 3.33066907387547E-16 4.3140731314173E-05"
        rpy="0 0 0" />
      <mass
        value="0.0139949492210214" />
      <inertia
        ixx="3.02502810414478E-06"
        ixy="-3.7277595740986E-21"
        ixz="-8.56055866655072E-10"
        iyy="1.71731248188302E-06"
        iyz="1.43466354682744E-22"
        izz="1.70788961196181E-06" />
    </inertial>
    <visual>
      <origin
        xyz="0 0 0"
        rpy="0 0 0" />
      <geometry>
        <mesh
          filename="package://kuka_urdf/meshes/link6.STL" />
      </geometry>
      <material
        name="">
        <color
          rgba="0.6 0.6 0.6 1" />
      </material>
    </visual>
    <collision>
      <origin
        xyz="0 0 0"
        rpy="0 0 0" />
      <geometry>
        <mesh
          filename="package://kuka_urdf/meshes/link6.STL" />
      </geometry>
    </collision>
  </link>
  <joint
    name="joint6"
    type="revolute">
    <origin
      xyz="0.0665 0 0"
      rpy="0 0 0" />
    <parent
      link="link5" />
    <child
      link="link6" />
    <axis
      xyz="1 0 0" />
    <limit
      lower="-6.28"
      upper="6.28"
      effort="500"
      velocity="2" />
  </joint>
</robot>