<?xml version="1.0" encoding="utf-8"?>
<!-- This URDF was automatically created by SolidWorks to URDF Exporter! Originally created by Stephen Brawner (brawner@gmail.com) 
     Commit Version: 1.5.1-0-g916b5db  Build Version: 1.5.7152.31018
     For more information, please see http://wiki.ros.org/sw_urdf_exporter -->
<robot
  name="kuka_urdf">
  <link
    name="base_link">
    <inertial>
      <origin
        xyz="0.594999467747321 1.10982733773241 0.428271087761206"
        rpy="0 0 0" />
      <mass
        value="170.00957643814" />
      <inertia
        ixx="15.4231911818268"
        ixy="-0.334753366098497"
        ixz="0.769988015661921"
        iyy="14.6780515806803"
        iyz="0.217841138291501"
        izz="21.0934965093949" />
    </inertial>
    <visual>
      <origin
        xyz="0 0 0"
        rpy="0 0 0" />
      <geometry>
        <mesh
          filename="package://kuka_urdf/meshes/base_link.STL" />
      </geometry>
      <material
        name="">
        <color
          rgba="0.752941176470588 0.752941176470588 0.752941176470588 1" />
      </material>
    </visual>
    <collision>
      <origin
        xyz="0 0 0"
        rpy="0 0 0" />
      <geometry>
        <mesh
          filename="package://kuka_urdf/meshes/base_link.STL" />
      </geometry>
    </collision>
  </link>
  <link
    name="link1">
    <inertial>
      <origin
        xyz="0.00796741917398325 0.00201869055885101 0.115718073498994"
        rpy="0 0 0" />
      <mass
        value="6.27526433045052" />
      <inertia
        ixx="0.0762054973038654"
        ixy="9.82188144569941E-06"
        ixz="-0.00530053527199465"
        iyy="0.0500772495062891"
        iyz="-0.000515039637430019"
        izz="0.0562692167501733" />
    </inertial>
    <visual>
      <origin
        xyz="0 0 0"
        rpy="0 0 0" />
      <geometry>
        <mesh
          filename="package://kuka_urdf/meshes/link1.STL" />
      </geometry>
      <material
        name="">
        <color
          rgba="0.792156862745098 0.819607843137255 0.933333333333333 1" />
      </material>
    </visual>
    <collision>
      <origin
        xyz="0 0 0"
        rpy="0 0 0" />
      <geometry>
        <mesh
          filename="package://kuka_urdf/meshes/link1.STL" />
      </geometry>
    </collision>
  </link>
  <joint
    name="joint1"
    type="revolute">
    <origin
      xyz="0.8275 -0.43219 1.3595"
      rpy="0 0 0" />
    <parent
      link="base_link" />
    <child
      link="link1" />
    <axis
      xyz="0 0 1" />
    <limit
      lower="-12.56"
      upper="12.56"
      effort="500"
      velocity="2" />
  </joint>
  <link
    name="link2">
    <inertial>
      <origin
        xyz="-0.00525474427373662 -0.00581945166654135 0.131443823398878"
        rpy="0 0 0" />
      <mass
        value="7.36258419830385" />
      <inertia
        ixx="0.151415780044457"
        ixy="-1.49717820004799E-05"
        ixz="0.000868975891906839"
        iyy="0.135639503717904"
        iyz="0.00168356968157077"
        izz="0.0384883579896224" />
    </inertial>
    <visual>
      <origin
        xyz="0 0 0"
        rpy="0 0 0" />
      <geometry>
        <mesh
          filename="package://kuka_urdf/meshes/link2.STL" />
      </geometry>
      <material
        name="">
        <color
          rgba="0.792156862745098 0.819607843137255 0.933333333333333 1" />
      </material>
    </visual>
    <collision>
      <origin
        xyz="0 0 0"
        rpy="0 0 0" />
      <geometry>
        <mesh
          filename="package://kuka_urdf/meshes/link2.STL" />
      </geometry>
    </collision>
  </link>
  <joint
    name="joint2"
    type="revolute">
    <origin
      xyz="0.025 0 0.183"
      rpy="0 0 0" />
    <parent
      link="link1" />
    <child
      link="link2" />
    <axis
      xyz="0 -1 0" />
    <limit
      lower="-12.56"
      upper="12.56"
      effort="500"
      velocity="2" />
  </joint>
  <link
    name="link3">
    <inertial>
      <origin
        xyz="0.0158897369187757 0.00377551618976696 0.0103622040607538"
        rpy="0 0 0" />
      <mass
        value="2.90698496734874" />
      <inertia
        ixx="0.00835937630352446"
        ixy="3.52504576818562E-05"
        ixz="-0.00140858847686176"
        iyy="0.0112132449448129"
        iyz="1.88954255172526E-05"
        izz="0.0100277382418828" />
    </inertial>
    <visual>
      <origin
        xyz="0 0 0"
        rpy="0 0 0" />
      <geometry>
        <mesh
          filename="package://kuka_urdf/meshes/link3.STL" />
      </geometry>
      <material
        name="">
        <color
          rgba="0.8 1 0.2 1" />
      </material>
    </visual>
    <collision>
      <origin
        xyz="0 0 0"
        rpy="0 0 0" />
      <geometry>
        <mesh
          filename="package://kuka_urdf/meshes/link3.STL" />
      </geometry>
    </collision>
  </link>
  <joint
    name="joint3"
    type="revolute">
    <origin
      xyz="0 0 0.315"
      rpy="0 0 0" />
    <parent
      link="link2" />
    <child
      link="link3" />
    <axis
      xyz="0 -1 0" />
    <limit
      lower="-12.56"
      upper="12.56"
      effort="500"
      velocity="2" />
  </joint>
  <link
    name="link4">
    <inertial>
      <origin
        xyz="0.123981724214701 0.00346882113244334 0.000289159358459745"
        rpy="0 0 0" />
      <mass
        value="2.75654210425904" />
      <inertia
        ixx="0.00584711964625554"
        ixy="-0.000156323136874247"
        ixz="5.19522467907691E-06"
        iyy="0.0156113113263976"
        iyz="1.44373593566698E-05"
        izz="0.0172713088405886" />
    </inertial>
    <visual>
      <origin
        xyz="0 0 0"
        rpy="0 0 0" />
      <geometry>
        <mesh
          filename="package://kuka_urdf/meshes/link4.STL" />
      </geometry>
      <material
        name="">
        <color
          rgba="0.792156862745098 0.819607843137255 0.933333333333333 1" />
      </material>
    </visual>
    <collision>
      <origin
        xyz="0 0 0"
        rpy="0 0 0" />
      <geometry>
        <mesh
          filename="package://kuka_urdf/meshes/link4.STL" />
      </geometry>
    </collision>
  </link>
  <joint
    name="joint4"
    type="revolute">
    <origin
      xyz="0.10695 0.003 0.035"
      rpy="0 0 0" />
    <parent
      link="link3" />
    <child
      link="link4" />
    <axis
      xyz="-1 0 0" />
    <limit
      lower="-12.56"
      upper="12.56"
      effort="500"
      velocity="2" />
  </joint>
  <link
    name="link5">
    <inertial>
      <origin
        xyz="0.0157891702201667 0.0019136754426482 -3.03958143459404E-05"
        rpy="0 0 0" />
      <mass
        value="0.442067197041371" />
      <inertia
        ixx="0.000318420757784039"
        ixy="1.66314420372699E-05"
        ixz="3.20639671747857E-07"
        iyy="0.000528480030475778"
        iyz="3.23079721639542E-07"
        izz="0.000562282896446415" />
    </inertial>
    <visual>
      <origin
        xyz="0 0 0"
        rpy="0 0 0" />
      <geometry>
        <mesh
          filename="package://kuka_urdf/meshes/link5.STL" />
      </geometry>
      <material
        name="">
        <color
          rgba="0.792156862745098 0.819607843137255 0.933333333333333 1" />
      </material>
    </visual>
    <collision>
      <origin
        xyz="0 0 0"
        rpy="0 0 0" />
      <geometry>
        <mesh
          filename="package://kuka_urdf/meshes/link5.STL" />
      </geometry>
    </collision>
  </link>
  <joint
    name="joint5"
    type="revolute">
    <origin
      xyz="0.25805 0 0"
      rpy="0 0 0" />
    <parent
      link="link4" />
    <child
      link="link5" />
    <axis
      xyz="0 1 0" />
    <limit
      lower="-12.56"
      upper="12.56"
      effort="500"
      velocity="2" />
  </joint>
  <link
    name="link6">
    <inertial>
      <origin
        xyz="0.005980331956146 2.77555756156289E-16 4.3140731314173E-05"
        rpy="0 0 0" />
      <mass
        value="0.0139949492210214" />
      <inertia
        ixx="3.02502810414478E-06"
        ixy="-3.73225880560227E-21"
        ixz="-8.56055866654648E-10"
        iyy="1.71731248188302E-06"
        iyz="1.07125006063243E-22"
        izz="1.70788961196181E-06" />
    </inertial>
    <visual>
      <origin
        xyz="0 0 0"
        rpy="0 0 0" />
      <geometry>
        <mesh
          filename="package://kuka_urdf/meshes/link6.STL" />
      </geometry>
      <material
        name="">
        <color
          rgba="0.6 0.6 0.6 1" />
      </material>
    </visual>
    <collision>
      <origin
        xyz="0 0 0"
        rpy="0 0 0" />
      <geometry>
        <mesh
          filename="package://kuka_urdf/meshes/link6.STL" />
      </geometry>
    </collision>
  </link>
  <joint
    name="joint6"
    type="revolute">
    <origin
      xyz="0.0665 0 0"
      rpy="0 0 0" />
    <parent
      link="link5" />
    <child
      link="link6" />
    <axis
      xyz="1 0 0" />
    <limit
      lower="-12.56"
      upper="12.56"
      effort="500"
      velocity="2" />
  </joint>
</robot>