<?xml version="1.0" encoding="utf-8"?>
<!-- This URDF was automatically created by SolidWorks to URDF Exporter! Originally created by Stephen Brawner (brawner@gmail.com) 
     Commit Version: 1.5.1-0-g916b5db  Build Version: 1.5.7152.31018
     For more information, please see http://wiki.ros.org/sw_urdf_exporter -->
<robot
  name="kuka_urdf">
  <link
    name="base_link">
    <inertial>
      <origin
        xyz="0.578233258845226 -0.427953822747016 1.10006999729089"
        rpy="0 0 0" />
      <mass
        value="156.699273713239" />
      <inertia
        ixx="15.3483916720076"
        ixy="-0.769890218667312"
        ixz="-0.333622669748493"
        iyy="20.9696858078628"
        iyz="-0.21782222630579"
        izz="14.5591699314294" />
    </inertial>
    <visual>
      <origin
        xyz="0 0 0"
        rpy="0 0 0" />
      <geometry>
        <mesh
          filename="package://kuka_urdf/meshes/base_link.STL" />
      </geometry>
      <material
        name="">
        <color
          rgba="0.752941176470588 0.752941176470588 0.752941176470588 1" />
      </material>
    </visual>
    <collision>
      <origin
        xyz="0 0 0"
        rpy="0 0 0" />
      <geometry>
        <mesh
          filename="package://kuka_urdf/meshes/base_link.STL" />
      </geometry>
    </collision>
  </link>
  <link
    name="Link1">
    <inertial>
      <origin
        xyz="-0.0351156705591721 0.000184791414012453 -0.134801459657782"
        rpy="0 0 0" />
      <mass
        value="13.310335827662" />
      <inertia
        ixx="0.0747995175973457"
        ixy="-9.77969830121166E-05"
        ixz="-0.00113073350324059"
        iyy="0.123810684850794"
        iyz="-1.89141220859297E-05"
        izz="0.118881621023302" />
    </inertial>
    <visual>
      <origin
        xyz="0 0 0"
        rpy="0 0 0" />
      <geometry>
        <mesh
          filename="package://kuka_urdf/meshes/Link1.STL" />
      </geometry>
      <material
        name="">
        <color
          rgba="0.996078431372549 0.996078431372549 1 1" />
      </material>
    </visual>
    <collision>
      <origin
        xyz="0 0 0"
        rpy="0 0 0" />
      <geometry>
        <mesh
          filename="package://kuka_urdf/meshes/Link1.STL" />
      </geometry>
    </collision>
  </link>
  <joint
    name="Joint1"
    type="continuous">
    <origin
      xyz="0.8275 -0.43219 1.3595"
      rpy="0 0 0" />
    <parent
      link="base_link" />
    <child
      link="Link1" />
    <axis
      xyz="0 1 0" />
    <limit
      lower="-100"
      upper="100"
      effort="500"
      velocity="2" />
  </joint>
  <link
    name="Link2">
    <inertial>
      <origin
        xyz="-0.0170325808260173 0.0020186905588519 -0.067281926501007"
        rpy="0 0 0" />
      <mass
        value="6.27526433045052" />
      <inertia
        ixx="0.0762054973038654"
        ixy="9.82188144569864E-06"
        ixz="-0.00530053527199465"
        iyy="0.0500772495062891"
        iyz="-0.000515039637430019"
        izz="0.0562692167501733" />
    </inertial>
    <visual>
      <origin
        xyz="0 0 0"
        rpy="0 0 0" />
      <geometry>
        <mesh
          filename="package://kuka_urdf/meshes/Link2.STL" />
      </geometry>
      <material
        name="">
        <color
          rgba="0.792156862745098 0.819607843137255 0.933333333333333 1" />
      </material>
    </visual>
    <collision>
      <origin
        xyz="0 0 0"
        rpy="0 0 0" />
      <geometry>
        <mesh
          filename="package://kuka_urdf/meshes/Link2.STL" />
      </geometry>
    </collision>
  </link>
  <joint
    name="Joint2"
    type="revolute">
    <origin
      xyz="0.025 0 0.183"
      rpy="0 0 0" />
    <parent
      link="Link1" />
    <child
      link="Link2" />
    <axis
      xyz="0 0 1" />
    <limit
      lower="-6.28"
      upper="6.28"
      effort="500"
      velocity="2" />
  </joint>
  <link
    name="Link3">
    <inertial>
      <origin
        xyz="-0.00525474427373585 -0.00581945166654008 -0.183556176601122"
        rpy="0 0 0" />
      <mass
        value="7.36258419830385" />
      <inertia
        ixx="0.151415780044457"
        ixy="-1.49717820004799E-05"
        ixz="0.000868975891906839"
        iyy="0.135639503717904"
        iyz="0.00168356968157077"
        izz="0.0384883579896224" />
    </inertial>
    <visual>
      <origin
        xyz="0 0 0"
        rpy="0 0 0" />
      <geometry>
        <mesh
          filename="package://kuka_urdf/meshes/Link3.STL" />
      </geometry>
      <material
        name="">
        <color
          rgba="0.792156862745098 0.819607843137255 0.933333333333333 1" />
      </material>
    </visual>
    <collision>
      <origin
        xyz="0 0 0"
        rpy="0 0 0" />
      <geometry>
        <mesh
          filename="package://kuka_urdf/meshes/Link3.STL" />
      </geometry>
    </collision>
  </link>
  <joint
    name="Joint3"
    type="revolute">
    <origin
      xyz="0 0 0.315"
      rpy="0 0 0" />
    <parent
      link="Link2" />
    <child
      link="Link3" />
    <axis
      xyz="0 -1 0" />
    <limit
      lower="-6.28"
      upper="6.28"
      effort="500"
      velocity="2" />
  </joint>
  <link
    name="Link4">
    <inertial>
      <origin
        xyz="-0.0910602630812216 0.000775516189770509 -0.0246377959392461"
        rpy="0 0 0" />
      <mass
        value="2.90698496734874" />
      <inertia
        ixx="0.00835937630352446"
        ixy="3.52504576818562E-05"
        ixz="-0.00140858847686176"
        iyy="0.0112132449448129"
        iyz="1.88954255172526E-05"
        izz="0.0100277382418828" />
    </inertial>
    <visual>
      <origin
        xyz="0 0 0"
        rpy="0 0 0" />
      <geometry>
        <mesh
          filename="package://kuka_urdf/meshes/Link4.STL" />
      </geometry>
      <material
        name="">
        <color
          rgba="0.8 1 0.2 1" />
      </material>
    </visual>
    <collision>
      <origin
        xyz="0 0 0"
        rpy="0 0 0" />
      <geometry>
        <mesh
          filename="package://kuka_urdf/meshes/Link4.STL" />
      </geometry>
    </collision>
  </link>
  <joint
    name="Joint4"
    type="revolute">
    <origin
      xyz="0.10695 0.003 0.035"
      rpy="0 0 0" />
    <parent
      link="Link3" />
    <child
      link="Link4" />
    <axis
      xyz="0 -1 0" />
    <limit
      lower="-6.28"
      upper="6.28"
      effort="500"
      velocity="2" />
  </joint>
  <link
    name="Link5">
    <inertial>
      <origin
        xyz="-0.1340682757853 0.00346882113244334 0.000289159358457303"
        rpy="0 0 0" />
      <mass
        value="2.75654210425904" />
      <inertia
        ixx="0.00584711964625554"
        ixy="-0.000156323136874247"
        ixz="5.19522467907712E-06"
        iyy="0.0156113113263976"
        iyz="1.44373593566698E-05"
        izz="0.0172713088405886" />
    </inertial>
    <visual>
      <origin
        xyz="0 0 0"
        rpy="0 0 0" />
      <geometry>
        <mesh
          filename="package://kuka_urdf/meshes/Link5.STL" />
      </geometry>
      <material
        name="">
        <color
          rgba="0.792156862745098 0.819607843137255 0.933333333333333 1" />
      </material>
    </visual>
    <collision>
      <origin
        xyz="0 0 0"
        rpy="0 0 0" />
      <geometry>
        <mesh
          filename="package://kuka_urdf/meshes/Link5.STL" />
      </geometry>
    </collision>
  </link>
  <joint
    name="Joint5"
    type="revolute">
    <origin
      xyz="0.25805 0 0"
      rpy="0 0 0" />
    <parent
      link="Link4" />
    <child
      link="Link5" />
    <axis
      xyz="-1 0 0" />
    <limit
      lower="-6.28"
      upper="6.28"
      effort="500"
      velocity="2" />
  </joint>
  <link
    name="Link6">
    <inertial>
      <origin
        xyz="-0.050710829779834 0.00191367544254872 -3.039581434372E-05"
        rpy="0 0 0" />
      <mass
        value="0.442067197041371" />
      <inertia
        ixx="0.000318420757784039"
        ixy="1.66314420372699E-05"
        ixz="3.20639671747857E-07"
        iyy="0.000528480030475778"
        iyz="3.23079721639542E-07"
        izz="0.000562282896446415" />
    </inertial>
    <visual>
      <origin
        xyz="0 0 0"
        rpy="0 0 0" />
      <geometry>
        <mesh
          filename="package://kuka_urdf/meshes/Link6.STL" />
      </geometry>
      <material
        name="">
        <color
          rgba="0.792156862745098 0.819607843137255 0.933333333333333 1" />
      </material>
    </visual>
    <collision>
      <origin
        xyz="0 0 0"
        rpy="0 0 0" />
      <geometry>
        <mesh
          filename="package://kuka_urdf/meshes/Link6.STL" />
      </geometry>
    </collision>
  </link>
  <joint
    name="Joint6"
    type="revolute">
    <origin
      xyz="0.0665 0 0"
      rpy="0 0 0" />
    <parent
      link="Link5" />
    <child
      link="Link6" />
    <axis
      xyz="0 1 0" />
    <limit
      lower="-6.28"
      upper="6.28"
      effort="500"
      velocity="2" />
  </joint>
  <link
    name="Link7">
    <inertial>
      <origin
        xyz="0.005980331956146 2.77555756156289E-16 4.3140731314173E-05"
        rpy="0 0 0" />
      <mass
        value="0.0139949492210214" />
      <inertia
        ixx="3.02502810414478E-06"
        ixy="-3.73225880560227E-21"
        ixz="-8.56055866654649E-10"
        iyy="1.71731248188302E-06"
        iyz="1.07125006063243E-22"
        izz="1.70788961196181E-06" />
    </inertial>
    <visual>
      <origin
        xyz="0 0 0"
        rpy="0 0 0" />
      <geometry>
        <mesh
          filename="package://kuka_urdf/meshes/Link7.STL" />
      </geometry>
      <material
        name="">
        <color
          rgba="0.6 0.6 0.6 1" />
      </material>
    </visual>
    <collision>
      <origin
        xyz="0 0 0"
        rpy="0 0 0" />
      <geometry>
        <mesh
          filename="package://kuka_urdf/meshes/Link7.STL" />
      </geometry>
    </collision>
  </link>
  <joint
    name="Joint7"
    type="revolute">
    <origin
      xyz="0 0 0"
      rpy="0 0 0" />
    <parent
      link="Link6" />
    <child
      link="Link7" />
    <axis
      xyz="1 0 0" />
    <limit
      lower="-6.28"
      upper="6.28"
      effort="500"
      velocity="2" />
  </joint>
</robot>